Workbook

Sheet acs2015_county_data
A1: CensusId | B1: State | C1: County | D1: TotalPop | E1: IncomePerCap | F1: WorkAtHome | G1: Employed | H1: PrivateWork | I1: PublicWork | J1: SelfEmployed | K1: FamilyWork | L1: Unemployment | M1: PublicWork_bin | N1: Unemployment_bin
A2: 1001 | B2: Alabama | C2: Autauga | D2: 55221 | E2: 24974 | F2: 1.8 | G2: 23986 | H2: 73.6 | I2: 20.9 | J2: 5.5 | K2: 0 | L2: 7.6 | M2: =IF(acs2015_county_data[[#This Row],[PublicWork]]>='Описательные характеристики'!$F$5,"да","нет") -> да | N2: =IF(acs2015_county_data[[#This Row],[Unemployment]]>='Описательные характеристики'!$I$5,"да","нет") -> да
A3: 1003 | B3: Alabama | C3: Baldwin | D3: 195121 | E3: 27317 | F3: 3.9 | G3: 85953 | H3: 81.5 | I3: 12.3 | J3: 5.8 | K3: 0.4 | L3: 7.5 | M3: =IF(acs2015_county_data[[#This Row],[PublicWork]]>='Описательные характеристики'!$F$5,"да","нет") -> нет | N3: =IF(acs2015_county_data[[#This Row],[Unemployment]]>='Описательные характеристики'!$I$5,"да","нет") -> нет
A4: 1005 | B4: Alabama | C4: Barbour | D4: 26932 | E4: 16824 | F4: 1.6 | G4: 8597 | H4: 71.8 | I4: 20.8 | J4: 7.3 | K4: 0.1 | L4: 17.6 | M4: =IF(acs2015_county_data[[#This Row],[PublicWork]]>='Описательные характеристики'!$F$5,"да","нет") -> да | N4: =IF(acs2015_county_data[[#This Row],[Unemployment]]>='Описательные характеристики'!$I$5,"да","нет") -> да
A5: 1007 | B5: Alabama | C5: Bibb | D5: 22604 | E5: 18431 | F5: 0.7 | G5: 8294 | H5: 76.8 | I5: 16.1 | J5: 6.7 | K5: 0.4 | L5: 8.3 | M5: =IF(acs2015_county_data[[#This Row],[PublicWork]]>='Описательные характеристики'!$F$5,"да","нет") -> нет | N5: =IF(acs2015_county_data[[#This Row],[Unemployment]]>='Описательные характеристики'!$I$5,"да","нет") -> да
A6: 1009 | B6: Alabama | C6: Blount | D6: 57710 | E6: 20532 | F6: 2.3 | G6: 22189 | H6: 82 | I6: 13.5 | J6: 4.2 | K6: 0.4 | L6: 7.7 | M6: =IF(acs2015_county_data[[#This Row],[PublicWork]]>='Описательные характеристики'!$F$5,"да","нет") -> нет | N6: =IF(acs2015_county_data[[#This Row],[Unemployment]]>='Описательные характеристики'!$I$5,"да","нет") -> да
A7: 1011 | B7: Alabama | C7: Bullock | D7: 10678 | E7: 17580 | F7: 2.8 | G7: 3865 | H7: 79.5 | I7: 15.1 | J7: 5.4 | K7: 0 | L7: 18 | M7: =IF(acs2015_county_data[[#This Row],[PublicWork]]>='Описательные характеристики'!$F$5,"да","нет") -> нет | N7: =IF(acs2015_county_data[[#This Row],[Unemployment]]>='Описательные характеристики'!$I$5,"да","нет") -> да
A8: 1013 | B8: Alabama | C8: Butler | D8: 20354 | E8: 18390 | F8: 1.7 | G8: 7813 | H8: 77.4 | I8: 16.2 | J8: 6.2 | K8: 0.2 | L8: 10.9 | M8: =IF(acs2015_county_data[[#This Row],[PublicWork]]>='Описательные характеристики'!$F$5,"да","нет") -> да | N8: =IF(acs2015_county_data[[#This Row],[Unemployment]]>='Описательные характеристики'!$I$5,"да","нет") -> да
A9: 1015 | B9: Alabama | C9: Calhoun | D9: 116648 | E9: 21374 | F9: 2.7 | G9: 47401 | H9: 74.1 | I9: 20.8 | J9: 5 | K9: 0.1 | L9: 12.3 | M9: =IF(acs2015_county_data[[#This Row],[PublicWork]]>='Описательные характеристики'!$F$5,"да","нет") -> да | N9: =IF(acs2015_county_data[[#This Row],[Unemployment]]>='Описательные характеристики'!$I$5,"да","нет") -> да
A10: 1017 | B10: Alabama | C10: Chambers | D10: 34079 | E10: 21071 | F10: 2.1 | G10: 13689 | H10: 85.1 | I10: 12.1 | J10: 2.8 | K10: 0 | L10: 8.9 | M10: =IF(acs2015_county_data[[#This Row],[PublicWork]]>='Описательные характеристики'!$F$5,"да","нет") -> нет | N10: =IF(acs2015_county_data[[#This Row],[Unemployment]]>='Описательные характеристики'!$I$5,"да","нет") -> да
A11: 1019 | B11: Alabama | C11: Cherokee | D11: 26008 | E11: 21811 | F11: 2.5 | G11: 10155 | H11: 73.1 | I11: 18.5 | J11: 7.9 | K11: 0.5 | L11: 7.9 | M11: =IF(acs2015_county_data[[#This Row],[PublicWork]]>='Описательные характеристики'!$F$5,"да","нет") -> да | N11: =IF(acs2015_county_data[[#This Row],[Unemployment]]>='Описательные характеристики'!$I$5,"да","нет") -> да
A12: 1021 | B12: Alabama | C12: Chilton | D12: 43819 | E12: 21399 | F12: 1.9 | G12: 17895 | H12: 80.3 | I12: 15.2 | J12: 4.1 | K12: 0.5 | L12: 9.1 | M12: =IF(acs2015_county_data[[#This Row],[PublicWork]]>='Описательные характеристики'!$F$5,"да","нет") -> нет | N12: =IF(acs2015_county_data[[#This Row],[Unemployment]]>='Описательные характеристики'!$I$5,"да","нет") -> да
A13: 1023 | B13: Alabama | C13: Choctaw | D13: 13395 | E13: 20755 | F13: 0.8 | G13: 4405 | H13: 77.5 | I13: 16.8 | J13: 5.4 | K13: 0.3 | L13: 13.6 | M13: =IF(acs2015_county_data[[#This Row],[PublicWork]]>='Описательные характеристики'!$F$5,"да","нет") -> да | N13: =IF(acs2015_county_data[[#This Row],[Unemployment]]>='Описательные характеристики'!$I$5,"да","нет") -> да
... A201: 6027 | B201: California | C201: Inyo | D201: 18373 | E201: 27850 | F201: 5.4 | G201: 8370 | H201: 62.4 | I201: 28.1 | J201: 9.5 | K201: 0 | L201: 6.8 | M201: =IF(acs2015_county_data[[#This Row],[PublicWork]]>='Описательные характеристики'!$F$5,"да","нет") -> да | N201: =IF(acs2015_county_data[[#This Row],[Unemployment]]>='Описательные характеристики'!$I$5,"да","нет") -> нет
A202: 6029 | B202: California | C202: Kern | E202: 20644 | F202: 2.9 | G202: 327294 | H202: 76.3 | I202: 17.2 | J202: 6.2 | K202: 0.2 | L202: 12.7 | M202: =IF(acs2015_county_data[[#This Row],[PublicWork]]>='Описательные характеристики'!$F$5,"да","нет") -> да | N202: =IF(acs2015_county_data[[#This Row],[Unemployment]]>='Описательные характеристики'!$I$5,"да","нет") -> да
A203: 6031 | B203: California | C203: Kings | D203: 150998 | E203: 18707 | F203: 3.2 | G203: 50960 | H203: 68.2 | I203: 25.7 | J203: 5.9 | K203: 0.2 | L203: 13 | M203: =IF(acs2015_county_data[[#This Row],[PublicWork]]>='Описательные характеристики'!$F$5,"да","нет") -> да | N203: =IF(acs2015_county_data[[#This Row],[Unemployment]]>='Описательные характеристики'!$I$5,"да","нет") -> да
A204: 6033 | B204: California | C204: Lake | D204: 64158 | E204: 21407 | F204: 11.2 | G204: 23011 | H204: 66 | I204: 22.2 | J204: 11.7 | K204: 0.2 | L204: 14.6 | M204: =IF(acs2015_county_data[[#This Row],[PublicWork]]>='Описательные характеристики'!$F$5,"да","нет") -> да | N204: =IF(acs2015_county_data[[#This Row],[Unemployment]]>='Описательные характеристики'!$I$5,"да","нет") -> да
A205: 6035 | B205: California | C205: Lassen | D205: 32645 | E205: 19274 | F205: 4.8 | G205: 9082 | H205: 42.6 | I205: 50.5 | J205: 6.8 | K205: 0.1 | L205: 10.9 | M205: =IF(acs2015_county_data[[#This Row],[PublicWork]]>='Описательные характеристики'!$F$5,"да","нет") -> да | N205: =IF(acs2015_county_data[[#This Row],[Unemployment]]>='Описательные характеристики'!$I$5,"да","нет") -> да
A206: 6037 | B206: California | C206: Los Angeles | D206: 10038388 | E206: 28337 | F206: 5.1 | G206: 4635465 | H206: 79 | I206: 11.5 | J206: 9.4 | K206: 0.2 | L206: 10 | M206: =IF(acs2015_county_data[[#This Row],[PublicWork]]>='Описательные характеристики'!$F$5,"да","нет") -> нет | N206: =IF(acs2015_county_data[[#This Row],[Unemployment]]>='Описательные характеристики'!$I$5,"да","нет") -> да
A207: 6039 | B207: California | C207: Madera | D207: 153187 | E207: 17970 | F207: 4.7 | G207: 53032 | H207: 76.5 | I207: 16 | J207: 7.4 | K207: 0.1 | L207: 7.5 | M207: =IF(acs2015_county_data[[#This Row],[PublicWork]]>='Описательные характеристики'!$F$5,"да","нет") -> нет | N207: =IF(acs2015_county_data[[#This Row],[Unemployment]]>='Описательные характеристики'!$I$5,"да","нет") -> нет
A208: 6041 | B208: California | C208: Marin | D208: 258349 | E208: 60236 | F208: 10.1 | G208: 129027 | H208: 73.8 | I208: 10.8 | J208: 15.4 | K208: 0.1 | L208: 5.7 | M208: =IF(acs2015_county_data[[#This Row],[PublicWork]]>='Описательные характеристики'!$F$5,"да","нет") -> нет | N208: =IF(acs2015_county_data[[#This Row],[Unemployment]]>='Описательные характеристики'!$I$5,"да","нет") -> нет
A209: 6043 | B209: California | C209: Mariposa | D209: 17789 | E209: 28316 | F209: 9 | G209: 7329 | H209: 60.3 | I209: 27.8 | J209: 10.5 | K209: 1.5 | L209: 11.6 | M209: =IF(acs2015_county_data[[#This Row],[PublicWork]]>='Описательные характеристики'!$F$5,"да","нет") -> да | N209: =IF(acs2015_county_data[[#This Row],[Unemployment]]>='Описательные характеристики'!$I$5,"да","нет") -> да
A210: 6045 | B210: California | C210: Mendocino | D210: 87544 | E210: 24059 | F210: 7.5 | G210: 36848 | H210: 64.9 | I210: 19.1 | J210: 15.4 | K210: 0.6 | L210: 12.2 | M210: =IF(acs2015_county_data[[#This Row],[PublicWork]]>='Описательные характеристики'!$F$5,"да","нет") -> да | N210: =IF(acs2015_county_data[[#This Row],[Unemployment]]>='Описательные характеристики'!$I$5,"да","нет") -> да
A211: 6047 | B211: California | C211: Merced | D211: 263885 | E211: 18204 | F211: 3.9 | G211: 96170 | H211: 76.7 | I211: 16.2 | J211: 7 | K211: 0.2 | L211: 16.2 | M211: =IF(acs2015_county_data[[#This Row],[PublicWork]]>='Описательные характеристики'!$F$5,"да","нет") -> да | N211: =IF(acs2015_county_data[[#This Row],[Unemployment]]>='Описательные характеристики'!$I$5,"да","нет") -> да
A212: 6049 | B212: California | C212: Modoc | D212: 9184 | E212: 21001 | F212: 12.8 | G212: 3334 | H212: 56.5 | I212: 31.3 | J212: 11.6 | K212: 0.6 | L212: 8.6 | M212: =IF(acs2015_county_data[[#This Row],[PublicWork]]>='Описательные характеристики'!$F$5,"да","нет") -> да | N212: =IF(acs2015_county_data[[#This Row],[Unemployment]]>='Описательные характеристики'!$I$5,"да","нет") -> да
A213: 6051 | B213: California | C213: Mono | D213: 14146 | E213: 29437 | F213: 12.9 | G213: 7061 | H213: 62.4 | I213: 25.9 | J213: 10.8 | K213: 0.9 | L213: 13.4 | M213: =IF(acs2015_county_data[[#This Row],[PublicWork]]>='Описательные характеристики'!$F$5,"да","нет") -> да | N213: =IF(acs2015_county_data[[#This Row],[Unemployment]]>='Описательные характеристики'!$I$5,"да","нет") -> да
A214: 6053 | B214: California | C214: Monterey | D214: 428441 | E214: 24994 | F214: 4.5 | G214: 177333 | H214: 76.6 | I214: 15.1 | J214: 8.2 | K214: 0.2 | L214: 8.4 | M214: =IF(acs2015_county_data[[#This Row],[PublicWork]]>='Описательные характеристики'!$F$5,"да","нет") -> нет | N214: =IF(acs2015_county_data[[#This Row],[Unemployment]]>='Описательные характеристики'!$I$5,"да","нет") -> да
... A440: 13105 | B440: Georgia | C440: Kingston | D440: 19537 | E440: 19841 | F440: 2.2 | G440: 7210 | H440: 74 | I440: 17.5 | J440: 8.4 | K440: 0.1 | L440: 10.8 | M440: =IF(acs2015_county_data[[#This Row],[PublicWork]]>='Описательные характеристики'!$F$5,"да","нет") -> да | N440: =IF(acs2015_county_data[[#This Row],[Unemployment]]>='Описательные характеристики'!$I$5,"да","нет") -> да
A441: 13107 | B441: Georgia | C441: Emanuel | D441: 22731 | E441: 17096 | F441: 1.4 | H441: 72.3 | I441: 19.7 | J441: 7.8 | K441: 0.2 | L441: 13.2 | M441: =IF(acs2015_county_data[[#This Row],[PublicWork]]>='Описательные характеристики'!$F$5,"да","нет") -> да | N441: =IF(acs2015_county_data[[#This Row],[Unemployment]]>='Описательные характеристики'!$I$5,"да","нет") -> да
A442: 13109 | B442: Georgia | C442: Evans | D442: 10814 | E442: 19625 | F442: 5.3 | G442: 3979 | H442: 72.6 | I442: 16.5 | J442: 10.6 | K442: 0.3 | L442: 10.3 | M442: =IF(acs2015_county_data[[#This Row],[PublicWork]]>='Описательные характеристики'!$F$5,"да","нет") -> да | N442: =IF(acs2015_county_data[[#This Row],[Unemployment]]>='Описательные характеристики'!$I$5,"да","нет") -> да
A443: 13111 | B443: Georgia | C443: Fannin | D443: 23742 | E443: 20534 | F443: 5.8 | G443: 8669 | H443: 73.4 | I443: 14.3 | J443: 12 | K443: 0.3 | L443: 12 | M443: =IF(acs2015_county_data[[#This Row],[PublicWork]]>='Описательные характеристики'!$F$5,"да","нет") -> нет | N443: =IF(acs2015_county_data[[#This Row],[Unemployment]]>='Описательные характеристики'!$I$5,"да","нет") -> да
A444: 13113 | B444: Georgia | C444: Fayette | D444: 108655 | E444: 36362 | F444: 7.1 | G444: 49795 | H444: 79.2 | I444: 15.8 | J444: 4.9 | K444: 0.1 | L444: 7.6 | M444: =IF(acs2015_county_data[[#This Row],[PublicWork]]>='Описательные характеристики'!$F$5,"да","нет") -> нет | N444: =IF(acs2015_county_data[[#This Row],[Unemployment]]>='Описательные характеристики'!$I$5,"да","нет") -> да
A445: 13115 | B445: Georgia | C445: Floyd | D445: 96169 | E445: 21218 | F445: 3.8 | G445: 39669 | H445: 81.7 | I445: 14.3 | J445: 3.8 | K445: 0.2 | L445: 10.9 | M445: =IF(acs2015_county_data[[#This Row],[PublicWork]]>='Описательные характеристики'!$F$5,"да","нет") -> нет | N445: =IF(acs2015_county_data[[#This Row],[Unemployment]]>='Описательные характеристики'!$I$5,"да","нет") -> да
A446: 13117 | B446: Georgia | C446: Forsyth | D446: 196236 | E446: 35696 | F446: 9.3 | G446: 92504 | H446: 84.1 | I446: 9.6 | J446: 6.2 | K446: 0.1 | L446: 6.2 | M446: =IF(acs2015_county_data[[#This Row],[PublicWork]]>='Описательные характеристики'!$F$5,"да","нет") -> нет | N446: =IF(acs2015_county_data[[#This Row],[Unemployment]]>='Описательные характеристики'!$I$5,"да","нет") -> нет
A447: 13119 | B447: Georgia | C447: Franklin | D447: 22110 | E447: 17743 | F447: 4.8 | G447: 8038 | H447: 78 | I447: 14.6 | J447: 7.3 | K447: 0 | L447: 8.4 | M447: =IF(acs2015_county_data[[#This Row],[PublicWork]]>='Описательные характеристики'!$F$5,"да","нет") -> нет | N447: =IF(acs2015_county_data[[#This Row],[Unemployment]]>='Описательные характеристики'!$I$5,"да","нет") -> да
A448: 13121 | B448: Georgia | C448: Fulton | D448: 983903 | E448: 37926 | F448: 7.9 | G448: 471816 | H448: 83.1 | I448: 11.5 | J448: 5.2 | K448: 0.1 | L448: 9.9 | M448: =IF(acs2015_county_data[[#This Row],[PublicWork]]>='Описательные характеристики'!$F$5,"да","нет") -> нет | N448: =IF(acs2015_county_data[[#This Row],[Unemployment]]>='Описательные характеристики'!$I$5,"да","нет") -> да
A449: 13123 | B449: Georgia | C449: Gilmer | D449: 28673 | E449: 21766 | F449: 4.4 | G449: 10938 | H449: 78.6 | I449: 9.5 | J449: 11.5 | K449: 0.5 | L449: 10 | M449: =IF(acs2015_county_data[[#This Row],[PublicWork]]>='Описательные характеристики'!$F$5,"да","нет") -> нет | N449: =IF(acs2015_county_data[[#This Row],[Unemployment]]>='Описательные характеристики'!$I$5,"да","нет") -> да
A450: 13125 | B450: Georgia | C450: Glascock | D450: 3087 | E450: 18921 | F450: 3.7 | G450: 1344 | H450: 75.2 | I450: 17.7 | J450: 6.9 | K450: 0.1 | L450: 7.1 | M450: =IF(acs2015_county_data[[#This Row],[PublicWork]]>='Описательные характеристики'!$F$5,"да","нет") -> да | N450: =IF(acs2015_county_data[[#This Row],[Unemployment]]>='Описательные характеристики'!$I$5,"да","нет") -> нет
A451: 13127 | B451: Georgia | C451: Glynn | D451: 81743 | E451: 26541 | F451: 4.2 | G451: 36375 | H451: 76.9 | I451: 17.1 | J451: 5.7 | K451: 0.3 | L451: 9.3 | M451: =IF(acs2015_county_data[[#This Row],[PublicWork]]>='Описательные характеристики'!$F$5,"да","нет") -> да | N451: =IF(acs2015_county_data[[#This Row],[Unemployment]]>='Описательные характеристики'!$I$5,"да","нет") -> да
A452: 13129 | B452: Georgia | C452: Gordon | D452: 55889 | E452: 19707 | F452: 2.7 | G452: 23587 | H452: 82.9 | I452: 11.4 | J452: 5.2 | K452: 0.5 | L452: 8.3 | M452: =IF(acs2015_county_data[[#This Row],[PublicWork]]>='Описательные характеристики'!$F$5,"да","нет") -> нет | N452: =IF(acs2015_county_data[[#This Row],[Unemployment]]>='Описательные характеристики'!$I$5,"да","нет") -> да
...

Sheet Описательные характеристики
A1: Количественные данные | B1: TotalPop | C1: IncomePerCap | D1: Employed | E1: PrivateWork | F1: PublicWork | G1: SelfEmployed | H1: FamilyWork | I1: Unemployment
A2: Среднее значение | B2: =AVERAGE(acs2015_county_data[TotalPop]) -> 99171.282 | C2: =AVERAGE(acs2015_county_data[IncomePerCap]) -> 23981.772 | D2: =AVERAGE(acs2015_county_data[Employed]) -> 45605.104 | E2: =AVERAGE(acs2015_county_data[PrivateWork]) -> 74.219348 | F2: =AVERAGE(acs2015_county_data[PublicWork]) -> 17.560143 | G2: =AVERAGE(acs2015_county_data[SelfEmployed]) -> 7.9318012 | H2: =AVERAGE(acs2015_county_data[FamilyWork]) -> 0.28810559 | I2: =AVERAGE(acs2015_county_data[Unemployment]) -> 8.094441
A3: Дисперсия | B3: =VAR(acs2015_county_data[TotalPop]) -> 1.0180511e+11 | C3: =VAR(acs2015_county_data[IncomePerCap]) -> 38493834 | D3: =VAR(acs2015_county_data[Employed]) -> 2.2416473e+10 | E3: =VAR(acs2015_county_data[PrivateWork]) -> 61.829725 | F3: =VAR(acs2015_county_data[PublicWork]) -> 42.383006 | G3: =VAR(acs2015_county_data[SelfEmployed]) -> 15.327022 | H3: =VAR(acs2015_county_data[FamilyWork]) -> 0.20714956 | I3: =VAR(acs2015_county_data[Unemployment]) -> 16.778152
A4: Среднеквадратичное отклонение | B4: =STDEV(acs2015_county_data[TotalPop]) -> 319069.13 | C4: =STDEV(acs2015_county_data[IncomePerCap]) -> 6204.34 | D4: =STDEV(acs2015_county_data[Employed]) -> 149721.32 | E4: =STDEV(acs2015_county_data[PrivateWork]) -> 7.863188 | F4: =STDEV(acs2015_county_data[PublicWork]) -> 6.5102232 | G4: =STDEV(acs2015_county_data[SelfEmployed]) -> 3.9149741 | H4: =STDEV(acs2015_county_data[FamilyWork]) -> 0.45513686 | I4: =STDEV(acs2015_county_data[Unemployment]) -> 4.0961142
A5: Медиана | B5: =MEDIAN(acs2015_county_data[TotalPop]) -> 26014 | C5: =MEDIAN(acs2015_county_data[IncomePerCap]) -> 23460 | D5: =MEDIAN(acs2015_county_data[Employed]) -> 10521 | E5: =MEDIAN(acs2015_county_data[PrivateWork]) -> 75.7 | F5: =MEDIAN(acs2015_county_data[PublicWork]) -> 16.2 | G5: =MEDIAN(acs2015_county_data[SelfEmployed]) -> 6.9 | H5: =MEDIAN(acs2015_county_data[FamilyWork]) -> 0.2 | I5: =MEDIAN(acs2015_county_data[Unemployment]) -> 7.6
A6: Мода | B6: =MODE(acs2015_county_data[TotalPop]) -> 8697 | C6: =MODE(acs2015_county_data[IncomePerCap]) -> 19743 | D6: =MODE(acs2015_county_data[Employed]) -> 6712 | E6: =MODE(acs2015_county_data[PrivateWork]) -> 79.8 | F6: =MODE(acs2015_county_data[PublicWork]) -> 13.8 | G6: =MODE(acs2015_county_data[SelfEmployed]) -> 5.7 | H6: =MODE(acs2015_county_data[FamilyWork]) -> 0.1 | I6: =MODE(acs2015_county_data[Unemployment]) -> 6.8
A9: Качественные данные | B9: State | C9: County
A10: Мода | B10: Texas | C10: Washington
A12: Количество по полю Unemployment | B12: Названия столбцов
A13: Названия строк | B13: да | C13: нет | D13: Общий итог
A14: да | B14: 932 | C14: 697 | D14: 1629
A15: нет | B15: 700 | C15: 891 | D15: 1591
A16: Общий итог | B16: 1632 | C16: 1588 | D16: 3220

Sheet Визуализация
A1: IncomePerCap | B1: Unemployment | C1: Unemployment_bin | M1: Интервалы | N1: Обозначение интервала | O1: Нижняя граница | P1: Верхняя граница | Q1: Частота
A2: 24974 | B2: 7.6 | C2: =IF(acs2015_county_data[[#This Row],[Unemployment]]>='Описательные характеристики'!$I$5,"да","нет") -> да | N2: <772263 | O2: 85 | P2: 772263 | Q2: 85
A3: 27317 | B3: 7.5 | C3: =IF(acs2015_county_data[[#This Row],[Unemployment]]>='Описательные характеристики'!$I$5,"да","нет") -> нет | N3: <1544441 | O3: 772263 | P3: 1544441 | Q3: 3144
A4: 16824 | B4: 17.6 | C4: =IF(acs2015_county_data[[#This Row],[Unemployment]]>='Описательные характеристики'!$I$5,"да","нет") -> да | N4: <2316619 | O4: 1544441 | P4: 2316619 | Q4: 0
A5: 18431 | B5: 8.3 | C5: =IF(acs2015_county_data[[#This Row],[Unemployment]]>='Описательные характеристики'!$I$5,"да","нет") -> да | N5: <3088797 | O5: 2316619 | P5: 3088797 | Q5: 52
A6: 20532 | B6: 7.7 | C6: =IF(acs2015_county_data[[#This Row],[Unemployment]]>='Описательные характеристики'!$I$5,"да","нет") -> да | N6: <3860975 | O6: 3088797 | P6: 3860975 | Q6: 0
A7: 17580 | B7: 18 | C7: =IF(acs2015_county_data[[#This Row],[Unemployment]]>='Описательные характеристики'!$I$5,"да","нет") -> да | N7: <4633153 | O7: 3860975 | P7: 4633153 | Q7: 14
A8: 18390 | B8: 10.9 | C8: =IF(acs2015_county_data[[#This Row],[Unemployment]]>='Описательные характеристики'!$I$5,"да","нет") -> да | N8: <5405331 | O8: 4633153 | P8: 5405331 | Q8: 0
A9: 21374 | B9: 12.3 | C9: =IF(acs2015_county_data[[#This Row],[Unemployment]]>='Описательные характеристики'!$I$5,"да","нет") -> да | N9: <6177509 | O9: 5405331 | P9: 6177509 | Q9: 3
A10: 21071 | B10: 8.9 | C10: =IF(acs2015_county_data[[#This Row],[Unemployment]]>='Описательные характеристики'!$I$5,"да","нет") -> да | N10: <6949687 | O10: 6177509 | P10: 6949687 | Q10: 0
A11: 21811 | B11: 7.9 | C11: =IF(acs2015_county_data[[#This Row],[Unemployment]]>='Описательные характеристики'!$I$5,"да","нет") -> да | N11: <7721865 | O11: 6949687 | P11: 7721865 | Q11: 2
A12: 21399 | B12: 9.1 | C12: =IF(acs2015_county_data[[#This Row],[Unemployment]]>='Описательные характеристики'!$I$5,"да","нет") -> да | N12: <8494043 | O12: 7721865 | P12: 8494043 | Q12: 0
A13: 20755 | B13: 13.6 | C13: =IF(acs2015_county_data[[#This Row],[Unemployment]]>='Описательные характеристики'!$I$5,"да","нет") -> да | N13: <9266221 | O13: 8494043 | P13: 9266221 | Q13: 2
A14: 20064 | B14: 19.4 | C14: =IF(acs2015_county_data[[#This Row],[Unemployment]]>='Описательные характеристики'!$I$5,"да","нет") -> да | N14: <10038389 | O14: 9266221 | P14: 10038389 | Q14: 0
A15: 18905 | B15: 9.4 | C15: =IF(acs2015_county_data[[#This Row],[Unemployment]]>='Описательные характеристики'!$I$5,"да","нет") -> да
A16: 20151 | B16: 8.3 | C16: =IF(acs2015_county_data[[#This Row],[Unemployment]]>='Описательные характеристики'!$I$5,"да","нет") -> да
A17: 24936 | B17: 7.1 | C17: =IF(acs2015_county_data[[#This Row],[Unemployment]]>='Описательные характеристики'!$I$5,"да","нет") -> нет
A18: 22546 | B18: 9 | C18: =IF(acs2015_county_data[[#This Row],[Unemployment]]>='Описательные характеристики'!$I$5,"да","нет") -> да
A19: 15968 | B19: 22.6 | C19: =IF(acs2015_county_data[[#This Row],[Unemployment]]>='Описательные характеристики'!$I$5,"да","нет") -> да
A20: 17519 | B20: 17 | C20: =IF(acs2015_county_data[[#This Row],[Unemployment]]>='Описательные характеристики'!$I$5,"да","нет") -> да
A21: 20977 | B21: 11.2 | C21: =IF(acs2015_county_data[[#This Row],[Unemployment]]>='Описательные характеристики'!$I$5,"да","нет") -> да
A22: 20585 | B22: 9.7 | C22: =IF(acs2015_county_data[[#This Row],[Unemployment]]>='Описательные характеристики'!$I$5,"да","нет") -> да
A23: 20881 | B23: 7.3 | C23: =IF(acs2015_county_data[[#This Row],[Unemployment]]>='Описательные характеристики'!$I$5,"да","нет") -> нет
A24: 22566 | B24: 10.9 | C24: =IF(acs2015_county_data[[#This Row],[Unemployment]]>='Описательные характеристики'!$I$5,"да","нет") -> да
A25: 17808 | B25: 16.4 | C25: =IF(acs2015_county_data[[#This Row],[Unemployment]]>='Описательные характеристики'!$I$5,"да","нет") -> да
A26: 18411 | B26: 7.7 | C26: =IF(acs2015_county_data[[#This Row],[Unemployment]]>='Описательные характеристики'!$I$5,"да","нет") -> да
... A34: 18877 | B34: 13.3 | C34: =IF(acs2015_county_data[[#This Row],[Unemployment]]>='Описательные характеристики'!$I$5,"да","нет") -> да
A35: 22931 | B35: 8.1 | C35: =IF(acs2015_county_data[[#This Row],[Unemployment]]>='Описательные характеристики'!$I$5,"да","нет") -> да | E35: PrivateWork | F35: PublicWork | G35: SelfEmployed | H35: FamilyWork
A36: 23925 | B36: 8.3 | C36: =IF(acs2015_county_data[[#This Row],[Unemployment]]>='Описательные характеристики'!$I$5,"да","нет") -> да | D36: Slope | E36: 56.1 | F36: 15.5 | G36: 27.5 | H36: 0.9
A37: 20066 | B37: 10.1 | C37: =IF(acs2015_county_data[[#This Row],[Unemployment]]>='Описательные характеристики'!$I$5,"да","нет") -> да | D37: Adjuntas | E37: 63 | F37: 28.7 | G37: 8 | H37: 0.3
A38: 27240 | B38: 9.1 | C38: =IF(acs2015_county_data[[#This Row],[Unemployment]]>='Описательные характеристики'!$I$5,"да","нет") -> да
A39: 20130 | B39: 10.2 | C39: =IF(acs2015_county_data[[#This Row],[Unemployment]]>='Описательные характеристики'!$I$5,"да","нет") -> да
A40: 24215 | B40: 7.1 | C40: =IF(acs2015_county_data[[#This Row],[Unemployment]]>='Описательные характеристики'!$I$5,"да","нет") -> нет
A41: 21369 | B41: 9.8 | C41: =IF(acs2015_county_data[[#This Row],[Unemployment]]>='Описательные характеристики'!$I$5,"да","нет") -> да
A42: 24356 | B42: 7.3 | C42: =IF(acs2015_county_data[[#This Row],[Unemployment]]>='Описательные характеристики'!$I$5,"да","нет") -> нет
A43: 25569 | B43: 7.8 | C43: =IF(acs2015_county_data[[#This Row],[Unemployment]]>='Описательные характеристики'!$I$5,"да","нет") -> да
A44: 18429 | B44: 13.2 | C44: =IF(acs2015_county_data[[#This Row],[Unemployment]]>='Описательные характеристики'!$I$5,"да","нет") -> да
A45: 17374 | B45: 16.9 | C45: =IF(acs2015_county_data[[#This Row],[Unemployment]]>='Описательные характеристики'!$I$5,"да","нет") -> да
A46: 32131 | B46: 8.5 | C46: =IF(acs2015_county_data[[#This Row],[Unemployment]]>='Описательные характеристики'!$I$5,"да","нет") -> да
A47: 21471 | B47: 11.4 | C47: =IF(acs2015_county_data[[#This Row],[Unemployment]]>='Описательные характеристики'!$I$5,"да","нет") -> да
...

Sheet Качественные признаки
A1: State | B1: Count
A2: District of Columbia | B2: =COUNTIF($B$2:$B$3221, A2) -> 1
A3: Delaware | B3: =COUNTIF($B$2:$B$3221, A3) -> 3
A4: Hawaii | B4: =COUNTIF($B$2:$B$3221, A4) -> 5
A5: Rhode Island | B5: =COUNTIF($B$2:$B$3221, A5) -> 5
A6: Connecticut | B6: =COUNTIF($B$2:$B$3221, A6) -> 8
A7: New Hampshire | B7: =COUNTIF($B$2:$B$3221, A7) -> 10
A8: Massachusetts | B8: =COUNTIF($B$2:$B$3221, A8) -> 14
A9: Vermont | B9: =COUNTIF($B$2:$B$3221, A9) -> 14
A10: Arizona | B10: =COUNTIF($B$2:$B$3221, A10) -> 15
A11: Maine | B11: =COUNTIF($B$2:$B$3221, A11) -> 16
A12: Nevada | B12: =COUNTIF($B$2:$B$3221, A12) -> 17
A13: New Jersey | B13: =COUNTIF($B$2:$B$3221, A13) -> 21
... A53: Texas | B53: =COUNTIF($B$2:$B$3221, A53) -> 254
